Workbook

Sheet 📖 Read Me First
A1: GatiGo — Revenue Forecasting & Driver-Based Model | FP&A Student Project
A2: This file forecasts GatiGo's revenue for Q2–Q4 FY2026 using a driver-based approach — where every revenue number is built from real business drivers, not just a % growth guess.
B3: What is Driver-Based Forecasting? | C3: Total Rides = Active Users × Rides per User per Month Ride Revenue = Total Rides × Avg Fare × Commission Rate Change any driver (users, fare, commission) → revenue updates automatically. This is how real FP&A teams forecast.
B4: What is in this file? | C4: Sheet 1 → This intro page Sheet 2 → Q1 Actuals recap (the starting point — matches GatiGo_Clean_Dashboard.xlsx) Sheet 3 → Revenue Drivers Table (the core forecasting engine) Sheet 4 → Scenario Analysis (Base / High Growth / Low Growth) Sheet 5 → Revenue Forecast Summary with charts Sheet 6 → Sensitivity Analysis (how sensitive is revenue to each driver?) Sheet 7 → Insights & Recommendations
B5: How to use this file | C5: 1. Start with Sheet 2 to understand Q1 actuals (do not edit — these are locked reference numbers) 2. Go to Sheet 3 (Revenue Drivers) — change the BLUE cells to try different assumptions 3. Sheet 4 lets you switch between 3 scenarios by changing one dropdown 4. Sheet 5 shows the full revenue forecast chart — it updates when you change Sheet 3 5. Read Sheet 7 for the business interpretation of what the numbers mean
B6: Colour Coding | C6: 🔵 Blue text = hardcoded input (you can change these) ⚫ Black text = calculated by a formula (do not change) 🟢 Green text = formula that pulls from another sheet 🟡 Yellow background = key input cell that you should look at
B7: Author & Disclaimer | C7: Model by Anjani Kumar Mishra Portfolio: https://inakm.github.io Project: https://inakm.github.io/page/projects/gatigo.html This is NOT a real startup. GatiGo is a design concept created for an academic entrepreneurship project. All financial figures are completely made up for learning purposes only.
A9: NOT a real startup. GatiGo is an academic design concept. All figures are hypothetical for learning purposes only. | B9: Model by Anjani Kumar Mishra

Sheet 📊 Q1 Actuals Recap
A1: GatiGo — Q1 FY2026 Actuals | Starting Point for Forecast
A2: These numbers are from the Actual P&L. They are the base (starting point) for all forecasts in this file.
A3: Line Item | B3: January | C3: February | D3: March | E3: Q1 Total
A4: RIDE VOLUME
A5: Active Users (estimated) | B5: 5600 | C5: 6400 | D5: 7500 | E5: =SUM(B5:D5) -> 19500
A6: Rides per User per Month | B6: 0.84 | C6: 0.75 | D6: 0.8
A7: Total Rides | B7: 4680 | C7: 4800 | D7: 5980 | E7: =SUM(B7:D7) -> 15460
A8: Avg Fare per Ride (₹) | B8: 150 | C8: 152 | D8: 155
A9: Working Days | B9: 26 | C9: 24 | D9: 26 | E9: =SUM(B9:D9) -> 76
A10: REVENUE BREAKDOWN
A11: Ride Commission Income (net GST, ₹) | B11: 89237 | C11: 92746 | D11: 117826 | E11: =SUM(B11:D11) -> 299809
A12: Intercity Ride Revenue (₹) | B12: 0 | C12: 3840 | D12: 7680 | E12: =SUM(B12:D12) -> 11520
A13: Corporate Partnership Fees (₹) | B13: 86400 | C13: 108000 | D13: 151200 | E13: =SUM(B13:D13) -> 345600
A14: Premium Subscription Revenue (₹) | B14: 55720 | C14: 69650 | D14: 83580 | E14: =SUM(B14:D14) -> 208950
A15: Advertising Revenue (₹) | B15: 18000 | C15: 20000 | D15: 22000 | E15: =SUM(B15:D15) -> 60000
A16: TOTAL REVENUE (₹) | B16: 249357 | C16: 294236 | D16: 382286 | E16: =SUM(B16:D16) -> 925879
A17: COST SUMMARY
A18: Total Cost of Revenue (₹) | B18: 278040 | C18: 291900 | D18: 340980 | E18: =SUM(B18:D18) -> 910920
A19: GROSS PROFIT (₹) | B19: -28683 | C19: 2336 | D19: 41306 | E19: =SUM(B19:D19) -> 14959
A20: Total Operating Expenses (₹) | B20: 463000 | C20: 481000 | D20: 517000 | E20: =SUM(B20:D20) -> 1461000
A21: EBITDA (₹) | B21: -491683 | C21: -478664 | D21: -475694 | E21: =SUM(B21:D21) -> -1446041
A22: NET PROFIT / LOSS (₹) | B22: -507683 | C22: -494664 | D22: -491694 | E22: =SUM(B22:D22) -> -1494041
A23: KEY METRICS
A24: Gross Margin % | B24: -0.115 | C24: 0.008 | D24: 0.108 | E24: 0.002
A25: EBITDA Margin % | B25: -1.972 | C25: -1.627 | D25: -1.244 | E25: -1.614
A26: Revenue per Ride (₹) | B26: 53.28 | C26: 61.3 | D26: 63.93
A27: New Users Acquired | B27: 600 | C27: 750 | D27: 900
A28: Premium Subscribers | B28: 280 | C28: 350 | D28: 420
A29: Corporate Clients | B29: 4 | C29: 5 | D29: 6
A31: NOT a real startup. GatiGo is an academic design concept. All figures are hypothetical for learning purposes only. | C31: Model by Anjani Kumar Mishra

Sheet 🔧 Revenue Drivers
A1: GatiGo — Revenue Driver Model | Q2–Q4 FY2026 Forecast (Blue cells = change these)
A2: Every revenue number below is calculated from the DRIVER INPUTS in yellow. Change a driver → all revenue lines update. This is driver-based forecasting.
A3: Driver / Assumption | B3: Apr | C3: May | D3: Jun | E3: Jul | F3: Aug | G3: Sep | H3: Oct | I3: Nov | J3: Dec | K3: Full Year (Q1+Q2+Q3+Q4)
A4: A — USER GROWTH DRIVERS (these drive ride volume)
A5: Active Users (starts from Q1 Mar ending: 7,500) | B5: 8100 | C5: =ROUND(B5*(1+C6),0) -> 8829 | D5: =ROUND(C5*(1+D6),0) -> 9624 | E5: =ROUND(D5*(1+E6),0) -> 10394 | F5: =ROUND(E5*(1+F6),0) -> 11226 | G5: =ROUND(F5*(1+G6),0) -> 12012 | H5: =ROUND(G5*(1+H6),0) -> 12853 | I5: =ROUND(H5*(1+I6),0) -> 13624 | J5: =ROUND(I5*(1+J6),0) -> 14441
A6: Monthly User Growth Rate (driven by marketing) | B6: 0.08 | C6: 0.09 | D6: 0.09 | E6: 0.08 | F6: 0.08 | G6: 0.07 | H6: 0.07 | I6: 0.06 | J6: 0.06
A7: New Users Acquired This Month (= Users this month − Users last month) | B7: =B5-7500 -> 600 | C7: =C5-B5 -> 729 | D7: =D5-C5 -> 795 | E7: =E5-D5 -> 770 | F7: =F5-E5 -> 832 | G7: =G5-F5 -> 786 | H7: =H5-G5 -> 841 | I7: =I5-H5 -> 771 | J7: =J5-I5 -> 817 | K7: =SUM(B7:J7) -> 6941
A8: B — RIDE VOLUME DRIVERS (users × rides per user = total rides)
A9: Rides per User per Month (grows slowly as users become regulars) | B9: 0.85 | C9: 0.87 | D9: 0.9 | E9: 0.92 | F9: 0.94 | G9: 0.95 | H9: 0.97 | I9: 0.98 | J9: 1
A10: Total Rides per Month (= Active Users × Rides per User) | B10: =ROUND(B5*B9,0) -> 6885 | C10: =ROUND(C5*C9,0) -> 7681 | D10: =ROUND(D5*D9,0) -> 8662 | E10: =ROUND(E5*E9,0) -> 9562 | F10: =ROUND(F5*F9,0) -> 10552 | G10: =ROUND(G5*G9,0) -> 11411 | H10: =ROUND(H5*H9,0) -> 12467 | I10: =ROUND(I5*I9,0) -> 13352 | J10: =ROUND(J5*J9,0) -> 14441 | K10: =SUM(B10:J10)+15460 -> 110473
A11: C — RIDE REVENUE DRIVERS (fare, commission, GST)
A12: Avg Ride Fare (₹) (Q1 actual: ₹150–155. Slight increase as demand grows) | B12: 156 | C12: 157 | D12: 158 | E12: 159 | F12: 160 | G12: 161 | H12: 162 | I12: 163 | J12: 165
A13: Commission Rate (GatiGo's cut of each fare — Q1 actual: 15%) | B13: 0.15 | C13: 0.15 | D13: 0.15 | E13: 0.155 | F13: 0.155 | G13: 0.155 | H13: 0.16 | I13: 0.16 | J13: 0.16
A14: GST Rate on Commission (18% — fixed by Indian tax law, do not change) | B14: 0.18 | C14: 0.18 | D14: 0.18 | E14: 0.18 | F14: 0.18 | G14: 0.18 | H14: 0.18 | I14: 0.18 | J14: 0.18
A15: Ride Commission Income (₹) [= Rides × Fare × Commission ÷ (1+GST)] | B15: =ROUND(B10*B12*B13/(1+B14),0) -> 136533 | C15: =ROUND(C10*C12*C13/(1+C14),0) -> 153295 | D15: =ROUND(D10*D12*D13/(1+D14),0) -> 173974 | E15: =ROUND(E10*E12*E13/(1+E14),0) -> 199708 | F15: =ROUND(F10*F12*F13/(1+F14),0) -> 221771 | G15: =ROUND(G10*G12*G13/(1+G14),0) -> 241323 | H15: =ROUND(H10*H12*H13/(1+H14),0) -> 273851 | I15: =ROUND(I10*I12*I13/(1+I14),0) -> 295102 | J15: =ROUND(J10*J12*J13/(1+J14),0) -> 323087 | K15: =SUM(B15:J15)+299809 -> 2318453
A16: D — OTHER REVENUE DRIVERS (corporate, subscriptions, ads, intercity)
A17: Corporate Clients (Q1 actual: 4/5/6. Growing via sales pipeline) | B17: 8 | C17: 9 | D17: 10 | E17: 12 | F17: 13 | G17: 14 | H17: 16 | I17: 17 | J17: 18
A18: Avg Monthly Contract per Corporate Client (₹) (Q1: ₹24–28K) | B18: 26000 | C18: 27000 | D18: 28000 | E18: 30000 | F18: 30000 | G18: 32000 | H18: 32000 | I18: 34000 | J18: 35000
A19: TDS Rate (Tax deducted by corporate clients) (10% — fixed by law) | B19: 0.1 | C19: 0.1 | D19: 0.1 | E19: 0.1 | F19: 0.1 | G19: 0.1 | H19: 0.1 | I19: 0.1 | J19: 0.1
A20: Corporate Revenue (₹) [= Clients × Contract × (1 − TDS)] | B20: =B17*B18*(1-B19) -> 187200 | C20: =C17*C18*(1-C19) -> 218700 | D20: =D17*D18*(1-D19) -> 252000 | E20: =E17*E18*(1-E19) -> 324000 | F20: =F17*F18*(1-F19) -> 351000 | G20: =G17*G18*(1-G19) -> 403200 | H20: =H17*H18*(1-H19) -> 460800 | I20: =I17*I18*(1-I19) -> 520200 | J20: =J17*J18*(1-J19) -> 567000 | K20: =SUM(B20:J20)+345600 -> 3629700
A21: Premium Subscribers (Q1 actual: 280/350/420. Growing via in-app prompt) | B21: 520 | C21: 600 | D21: 680 | E21: 760 | F21: 840 | G21: 900 | H21: 960 | I21: 1020 | J21: 1080
A22: Premium Subscription Price (₹/month) (Q1: ₹199 flat) | B22: 199 | C22: 199 | D22: 199 | E22: 199 | F22: 199 | G22: 199 | H22: 199 | I22: 199 | J22: 199
A23: Premium Subscription Revenue (₹) [= Subscribers × Price] | B23: =B21*B22 -> 103480 | C23: =C21*C22 -> 119400 | D23: =D21*D22 -> 135320 | E23: =E21*E22 -> 151240 | F23: =F21*F22 -> 167160 | G23: =G21*G22 -> 179100 | H23: =H21*H22 -> 191040 | I23: =I21*I22 -> 202980 | J23: =J21*J22 -> 214920 | K23: =SUM(B23:J23)+208950 -> 1673590
A24: Advertising Revenue (₹) (tracks active users — grows with platform) | B24: 24000 | C24: 27000 | D24: 30000 | E24: 33000 | F24: 37000 | G24: 40000 | H24: 43000 | I24: 46000 | J24: 50000 | K24: =SUM(B24:J24)+60000 -> 390000
A25: Intercity Rides / Month (Q1 actual: 0/40/80. Launched mid-Feb) | B25: 120 | C25: 160 | D25: 200 | E25: 240 | F25: 280 | G25: 320 | H25: 360 | I25: 400 | J25: 440
A26: Intercity Avg Fare (₹) (Q1: ₹800. Slight increase expected) | B26: 820 | C26: 830 | D26: 840 | E26: 850 | F26: 860 | G26: 870 | H26: 880 | I26: 890 | J26: 900
A27: Intercity Commission Rate (Q1: 12%) | B27: 0.12 | C27: 0.12 | D27: 0.12 | E27: 0.12 | F27: 0.12 | G27: 0.12 | H27: 0.12 | I27: 0.12 | J27: 0.12
A28: Intercity Revenue (₹) [= Intercity Rides × Fare × Commission] | B28: =ROUND(B25*B26*B27,0) -> 11808 | C28: =ROUND(C25*C26*C27,0) -> 15936 | D28: =ROUND(D25*D26*D27,0) -> 20160 | E28: =ROUND(E25*E26*E27,0) -> 24480 | F28: =ROUND(F25*F26*F27,0) -> 28896 | G28: =ROUND(G25*G26*G27,0) -> 33408 | H28: =ROUND(H25*H26*H27,0) -> 38016 | I28: =ROUND(I25*I26*I27,0) -> 42720 | J28: =ROUND(J25*J26*J27,0) -> 47520 | K28: =SUM(B28:J28)+11520 -> 274464
A29: TOTAL REVENUE (sum of all revenue streams)
A30: TOTAL REVENUE (₹) [= Ride + Intercity + Corporate + Premium + Ads] | B30: =B15+B28+B20+B23+B24 -> 463021 | C30: =C15+C28+C20+C23+C24 -> 534331 | D30: =D15+D28+D20+D23+D24 -> 611454 | E30: =E15+E28+E20+E23+E24 -> 732428 | F30: =F15+F28+F20+F23+F24 -> 805827 | G30: =G15+G28+G20+G23+G24 -> 897031 | H30: =H15+H28+H20+H23+H24 -> 1006707 | I30: =I15+I28+I20+I23+I24 -> 1107002 | J30: =J15+J28+J20+J23+J24 -> 1202527 | K30: =SUM(B30:J30)+925879 -> 8286207
A31: Check: Revenue per Ride (₹) [= Total Revenue ÷ Total Rides — should be ₹50-80] | B31: =IFERROR(B30/B10,0) -> 67.25069 | C31: =IFERROR(C30/C10,0) -> 69.565291 | D31: =IFERROR(D30/D10,0) -> 70.590395 | E31: =IFERROR(E30/E10,0) -> 76.597783 | F31: =IFERROR(F30/F10,0) -> 76.367229 | G31: =IFERROR(G30/G10,0) -> 78.611077 | H31: =IFERROR(H30/H10,0) -> 80.749739 | I31: =IFERROR(I30/I10,0) -> 82.909077 | J31: =IFERROR(J30/J10,0) -> 83.271726
A32: Month-on-Month Revenue Growth % | B32: =IFERROR(B30/382286-1,0) -> 0.21119005 | C32: =IFERROR(C30/B30-1,0) -> 0.15401029 | D32: =IFERROR(D30/C30-1,0) -> 0.14433563 | E32: =IFERROR(E30/D30-1,0) -> 0.19784644 | F32: =IFERROR(F30/E30-1,0) -> 0.10021326 | G32: =IFERROR(G30/F30-1,0) -> 0.11318062 | H32: =IFERROR(H30/G30-1,0) -> 0.12226556 | I32: =IFERROR(I30/H30-1,0) -> 0.099626803 | J32: =IFERROR(J30/I30-1,0) -> 0.086291624
A35: NOT a real startup. GatiGo is an academic design concept. All figures are hypothetical for learning purposes only. | F35: Model by Anjani Kumar Mishra

Sheet 🎯 Scenario Analysis
A1: GatiGo — Scenario Analysis | Base / High Growth / Low Growth
A2: Three scenarios based on different business outcomes. All numbers link to 'Revenue Drivers' sheet — change the drivers there to update scenarios.
A3: HOW EACH SCENARIO DIFFERS — Change these inputs in the Revenue Drivers sheet
A4: Driver | B4: Base Case | C4: High Growth | D4: Low Growth | F4: Unit | G4: What this means
A5: Monthly User Growth Rate | B5: 8–9% | C5: 12–15% | D5: 4–5% | F5: % | G5: Higher growth needs more marketing spend
A6: Rides per User per Month | B6: 0.85–1.0 | C6: 1.0–1.3 | D6: 0.6–0.8 | F6: /user | G6: Frequency improves as app becomes habit
A7: Avg Ride Fare (₹) | B7: ₹156–165 | C7: ₹160–175 | D7: ₹145–155 | F7: ₹ | G7: Surge pricing vs competitor pressure
A8: Corporate Clients | B8: 8–18 | C8: 12–25 | D8: 5–12 | F8: # | G8: Fast vs slow corporate sales pipeline
A9: Premium Subscribers | B9: 520–1080 | C9: 700–1500 | D9: 300–700 | F9: # | G9: In-app conversion rate varies
A10: Commission Rate | B10: 15–16% | C10: 15–16% | D10: 14–15% | F10: % | G10: Base stays, High can push slightly, Low pressure
A11: Marketing Spend | B11: Base | C11: +30% | D11: -25% | F11: ₹ | G11: High growth needs more ad spend
A12: Advertising Revenue | B12: ₹24–50K | C12: ₹35–70K | D12: ₹15–30K | F12: ₹ | G12: More users = more ad impressions
A14: BASE CASE (most likely outcome)
A15: This matches what the Revenue Drivers sheet shows. Steady user growth of 8–9%/month, rides per user improving slowly, corporate clients growing via BD hire. Most realistic scenario.
A16: Line | B16: Apr | C16: May | D16: Jun | E16: Q2 Total | F16: Q3 Total | G16: Q4 Total | H16: Full Year
A17: Active Users | B17: 8100 | C17: 8748 | D17: 9448 | E17: 26296 | F17: 32942 | G17: 39730 | H17: 98968
A18: Total Rides | B18: 6885 | C18: 7611 | D18: 8503 | E18: 22999 | F18: 30879 | G18: 39091 | H18: 92969
A19: Ride Commission Rev (₹) | B19: 141084 | C19: 156961 | D19: 176473 | E19: 474518 | F19: 649212 | G19: 839071 | H19: 1962801
A20: Intercity Revenue (₹) | B20: 11808 | C20: 15936 | D20: 20160 | E20: 47904 | F20: 86784 | G20: 128256 | H20: 262944
A21: Corporate Revenue (₹) | B21: 187200 | C21: 218700 | D21: 252000 | E21: 657900 | F21: 1078200 | G21: 1548000 | H21: 3284100
A22: Premium Revenue (₹) | B22: 103480 | C22: 119400 | D22: 135320 | E22: 358200 | F22: 497500 | G22: 608940 | H22: 1464640
A23: Advertising Revenue (₹) | B23: 24000 | C23: 27000 | D23: 30000 | E23: 81000 | F23: 110000 | G23: 139000 | H23: 330000
A24: TOTAL REVENUE (₹) | B24: 467572 | C24: 537997 | D24: 613953 | E24: 1619522 | F24: 2421696 | G24: 3263267 | H24: 8230364
A27: HIGH GROWTH (if marketing spend increases +30%)
A28: Users grow 12–15%/month due to aggressive marketing. Rides per user improves faster as app becomes the default choice. Corporate pipeline converts faster. Requires ₹30K+ extra marketing/month.
A29: Line | B29: Apr | C29: May | D29: Jun | E29: Q2 Total | F29: Q3 Total | G29: Q4 Total | H29: Full Year
A30: Active Users | B30: 8700 | C30: 9918 | D30: 11306 | E30: 29924 | F30: 44140 | G30: 62817 | H30: 136881
A31: Total Rides | B31: 8700 | C31: 10414 | D31: 12437 | E31: 31551 | F31: 53152 | G31: 81290 | H31: 165993
A32: Ride Commission Rev (₹) | B32: 180562 | C32: 218871 | D32: 264655 | E32: 664088 | F32: 1168281 | G32: 1859690 | H32: 3692059
A33: Intercity Revenue (₹) | B33: 16531 | C33: 22310 | D33: 28224 | E33: 67065 | F33: 121497 | G33: 179558 | H33: 368120
A34: Corporate Revenue (₹) | B34: 252000 | C34: 324000 | D34: 403200 | E34: 979200 | F34: 1924200 | G34: 3169800 | H34: 6073200
A35: Premium Revenue (₹) | B35: 123380 | C35: 147260 | D35: 175120 | E35: 445760 | F35: 718390 | G35: 1038780 | H35: 2202930
A36: Advertising Revenue (₹) | B36: 30000 | C36: 35000 | D36: 42000 | E36: 107000 | F36: 174000 | G36: 246000 | H36: 527000
A37: TOTAL REVENUE (₹) | B37: 602473 | C37: 747441 | D37: 913199 | E37: 2263113 | F37: 4106368 | G37: 6493828 | H37: 13789188
A40: LOW GROWTH (if competition increases or demand falls)
A41: User growth slows to 4–5%/month due to competitor pressure from QuickRide. Rides per user stays flat. Corporate onboarding delays. This scenario may require additional funding to survive.
A42: Line | B42: Apr | C42: May | D42: Jun | E42: Q2 Total | F42: Q3 Total | G42: Q4 Total | H42: Full Year
A43: Active Users | B43: 7800 | C43: 8190 | D43: 8600 | E43: 24590 | F43: 28366 | G43: 32155 | H43: 85111
A44: Total Rides | B44: 5460 | C44: 5897 | D44: 6364 | E44: 17721 | F44: 21184 | G44: 24768 | H44: 63673
A45: Ride Commission Rev (₹) | B45: 100640 | C45: 108695 | D45: 118085 | E45: 327420 | F45: 394853 | G45: 466727 | H45: 1189000
...

Sheet 📈 Forecast Summary
A1: GatiGo — Full Year Revenue Forecast | FY2026 (Jan–Dec)
A2: Jan–Mar = Q1 Actuals. Apr–Dec = Forecast from Revenue Drivers sheet.
A3: Line Item | B3: Jan | C3: Feb | D3: Mar | E3: Q1 | F3: Apr | G3: May | H3: Jun | I3: Q2 | J3: Jul | K3: Aug | L3: Sep | M3: Q3 | N3: Oct | O3: Nov | P3: Dec | Q3: Q4 | R3: Full Year
A4: RIDE VOLUME
A5: Active Users | B5: 5600 | C5: 6400 | D5: 7500 | E5: =SUM(B5:D5) -> 19500 | F5: ='🔧 Revenue Drivers'!B5 -> 8100 | G5: ='🔧 Revenue Drivers'!C5 -> 8829 | H5: ='🔧 Revenue Drivers'!D5 -> 9624 | I5: =F5+G5+H5 -> 26553 | J5: ='🔧 Revenue Drivers'!E5 -> 10394 | K5: ='🔧 Revenue Drivers'!F5 -> 11226 | L5: ='🔧 Revenue Drivers'!G5 -> 12012 | M5: =J5+K5+L5 -> 33632 | N5: ='🔧 Revenue Drivers'!H5 -> 12853 | O5: ='🔧 Revenue Drivers'!I5 -> 13624 | P5: ='🔧 Revenue Drivers'!J5 -> 14441 | Q5: =N5+O5+P5 -> 40918 | R5: =E5+I5+M5+Q5 -> 120603
A6: Total Rides | B6: 4680 | C6: 4800 | D6: 5980 | E6: 15460 | F6: ='🔧 Revenue Drivers'!B10 -> 6885 | G6: ='🔧 Revenue Drivers'!C10 -> 7681 | H6: ='🔧 Revenue Drivers'!D10 -> 8662 | I6: =F6+G6+H6 -> 23228 | J6: ='🔧 Revenue Drivers'!E10 -> 9562 | K6: ='🔧 Revenue Drivers'!F10 -> 10552 | L6: ='🔧 Revenue Drivers'!G10 -> 11411 | M6: =J6+K6+L6 -> 31525 | N6: ='🔧 Revenue Drivers'!H10 -> 12467 | O6: ='🔧 Revenue Drivers'!I10 -> 13352 | P6: ='🔧 Revenue Drivers'!J10 -> 14441 | Q6: =N6+O6+P6 -> 40260 | R6: =E6+I6+M6+Q6 -> 110473
A7: REVENUE STREAMS
A8: Ride Commission (₹) | B8: 89237 | C8: 92746 | D8: 117826 | E8: 299809 | F8: ='🔧 Revenue Drivers'!B15 -> 136533 | G8: ='🔧 Revenue Drivers'!C15 -> 153295 | H8: ='🔧 Revenue Drivers'!D15 -> 173974 | I8: =F8+G8+H8 -> 463802 | J8: ='🔧 Revenue Drivers'!E15 -> 199708 | K8: ='🔧 Revenue Drivers'!F15 -> 221771 | L8: ='🔧 Revenue Drivers'!G15 -> 241323 | M8: =J8+K8+L8 -> 662802 | N8: ='🔧 Revenue Drivers'!H15 -> 273851 | O8: ='🔧 Revenue Drivers'!I15 -> 295102 | P8: ='🔧 Revenue Drivers'!J15 -> 323087 | Q8: =N8+O8+P8 -> 892040 | R8: =E8+I8+M8+Q8 -> 2318453
A9: Intercity Revenue (₹) | B9: 0 | C9: 3840 | D9: 7680 | E9: 11520 | F9: ='🔧 Revenue Drivers'!B28 -> 11808 | G9: ='🔧 Revenue Drivers'!C28 -> 15936 | H9: ='🔧 Revenue Drivers'!D28 -> 20160 | I9: =F9+G9+H9 -> 47904 | J9: ='🔧 Revenue Drivers'!E28 -> 24480 | K9: ='🔧 Revenue Drivers'!F28 -> 28896 | L9: ='🔧 Revenue Drivers'!G28 -> 33408 | M9: =J9+K9+L9 -> 86784 | N9: ='🔧 Revenue Drivers'!H28 -> 38016 | O9: ='🔧 Revenue Drivers'!I28 -> 42720 | P9: ='🔧 Revenue Drivers'!J28 -> 47520 | Q9: =N9+O9+P9 -> 128256 | R9: =E9+I9+M9+Q9 -> 274464
A10: Corporate Fees (₹) | B10: 86400 | C10: 108000 | D10: 151200 | E10: 345600 | F10: ='🔧 Revenue Drivers'!B20 -> 187200 | G10: ='🔧 Revenue Drivers'!C20 -> 218700 | H10: ='🔧 Revenue Drivers'!D20 -> 252000 | I10: =F10+G10+H10 -> 657900 | J10: ='🔧 Revenue Drivers'!E20 -> 324000 | K10: ='🔧 Revenue Drivers'!F20 -> 351000 | L10: ='🔧 Revenue Drivers'!G20 -> 403200 | M10: =J10+K10+L10 -> 1078200 | N10: ='🔧 Revenue Drivers'!H20 -> 460800 | O10: ='🔧 Revenue Drivers'!I20 -> 520200 | P10: ='🔧 Revenue Drivers'!J20 -> 567000 | Q10: =N10+O10+P10 -> 1548000 | R10: =E10+I10+M10+Q10 -> 3629700
A11: Premium Subs (₹) | B11: 55720 | C11: 69650 | D11: 83580 | E11: 208950 | F11: ='🔧 Revenue Drivers'!B23 -> 103480 | G11: ='🔧 Revenue Drivers'!C23 -> 119400 | H11: ='🔧 Revenue Drivers'!D23 -> 135320 | I11: =F11+G11+H11 -> 358200 | J11: ='🔧 Revenue Drivers'!E23 -> 151240 | K11: ='🔧 Revenue Drivers'!F23 -> 167160 | L11: ='🔧 Revenue Drivers'!G23 -> 179100 | M11: =J11+K11+L11 -> 497500 | N11: ='🔧 Revenue Drivers'!H23 -> 191040 | O11: ='🔧 Revenue Drivers'!I23 -> 202980 | P11: ='🔧 Revenue Drivers'!J23 -> 214920 | Q11: =N11+O11+P11 -> 608940 | R11: =E11+I11+M11+Q11 -> 1673590
A12: Advertising (₹) | B12: 18000 | C12: 20000 | D12: 22000 | E12: 60000 | F12: ='🔧 Revenue Drivers'!B24 -> 24000 | G12: ='🔧 Revenue Drivers'!C24 -> 27000 | H12: ='🔧 Revenue Drivers'!D24 -> 30000 | I12: =F12+G12+H12 -> 81000 | J12: ='🔧 Revenue Drivers'!E24 -> 33000 | K12: ='🔧 Revenue Drivers'!F24 -> 37000 | L12: ='🔧 Revenue Drivers'!G24 -> 40000 | M12: =J12+K12+L12 -> 110000 | N12: ='🔧 Revenue Drivers'!H24 -> 43000 | O12: ='🔧 Revenue Drivers'!I24 -> 46000 | P12: ='🔧 Revenue Drivers'!J24 -> 50000 | Q12: =N12+O12+P12 -> 139000 | R12: =E12+I12+M12+Q12 -> 390000
A13: TOTAL REVENUE (₹) | B13: 249357 | C13: 294236 | D13: 382286 | E13: 925879 | F13: ='🔧 Revenue Drivers'!B30 -> 463021 | G13: ='🔧 Revenue Drivers'!C30 -> 534331 | H13: ='🔧 Revenue Drivers'!D30 -> 611454 | I13: =F13+G13+H13 -> 1608806 | J13: ='🔧 Revenue Drivers'!E30 -> 732428 | K13: ='🔧 Revenue Drivers'!F30 -> 805827 | L13: ='🔧 Revenue Drivers'!G30 -> 897031 | M13: =J13+K13+L13 -> 2435286 | N13: ='🔧 Revenue Drivers'!H30 -> 1006707 | O13: ='🔧 Revenue Drivers'!I30 -> 1107002 | P13: ='🔧 Revenue Drivers'!J30 -> 1202527 | Q13: =N13+O13+P13 -> 3316236 | R13: =E13+I13+M13+Q13 -> 8286207
A14: GROWTH METRICS
A15: Revenue MoM Growth % | B15: "-" | C15: 0.18 | D15: 0.299 | F15: =IFERROR('🔧 Revenue Drivers'!B30/382286-1,0) -> 0.21119005 | G15: ='🔧 Revenue Drivers'!C32 -> 0.15401029 | H15: ='🔧 Revenue Drivers'!D32 -> 0.14433563 | J15: ='🔧 Revenue Drivers'!E32 -> 0.19784644 | K15: ='🔧 Revenue Drivers'!F32 -> 0.10021326 | L15: ='🔧 Revenue Drivers'!G32 -> 0.11318062 | N15: ='🔧 Revenue Drivers'!H32 -> 0.12226556 | O15: ='🔧 Revenue Drivers'!I32 -> 0.099626803 | P15: ='🔧 Revenue Drivers'!J32 -> 0.086291624
A18: GatiGo is an academic design concept. All figures are hypothetical for learning purposes only. | J18: Model by Anjani Kumar Mishra

Sheet 🔍 Sensitivity Analysis
A1: GatiGo — Sensitivity Analysis | Which Drivers Matter Most?
A2: This table shows: if we change one driver by a fixed amount, how much does Q2 revenue change? This tells us which drivers to focus on.
A3: Driver Being Tested | B3: -20% change | C3: -10% change | D3: Base (no change) | E3: +10% change | F3: +20% change | G3: Sensitivity — which matters most?
A4: Base Q2 Revenue (from Revenue Drivers sheet) | D4: ='🔧 Revenue Drivers'!B30+'🔧 Revenue Drivers'!C30+'🔧 Revenue Drivers'!D30 -> 1608806
A5: HOW MUCH DOES Q2 REVENUE CHANGE IF WE ADJUST ONE DRIVER?
A6: Number of Active Users | B6: =$D$4*(1+(0.95*-0.2)) -> 1303132.9 | C6: =$D$4*(1+(0.95*-0.1)) -> 1455969.4 | D6: $D$4 | E6: =$D$4*(1+(0.95*0.1)) -> 1761642.6 | F6: =$D$4*(1+(0.95*0.2)) -> 1914479.1 | G6: MOST IMPORTANT. Users drive rides, which drive 2 revenue streams (commission + intercity). A 10% user increase raises Q2 revenue by roughly ₹1.1L. Focus on user acquisition first.
A7: Rides per User per Month | B7: =$D$4*(1+(0.38*-0.2)) -> 1486536.7 | C7: =$D$4*(1+(0.38*-0.1)) -> 1547671.4 | D7: $D$4 | E7: =$D$4*(1+(0.38*0.1)) -> 1669940.6 | F7: =$D$4*(1+(0.38*0.2)) -> 1731075.3 | G7: VERY IMPORTANT. More rides from existing users = more commission with zero extra acquisition cost. Target: push average from 0.85 to 1.0+ via push notifications and habit loops.
A8: Avg Ride Fare (₹) | B8: =$D$4*(1+(0.38*-0.2)) -> 1486536.7 | C8: =$D$4*(1+(0.38*-0.1)) -> 1547671.4 | D8: $D$4 | E8: =$D$4*(1+(0.38*0.1)) -> 1669940.6 | F8: =$D$4*(1+(0.38*0.2)) -> 1731075.3 | G8: MODERATE. A ₹10 fare increase (6%) raises revenue by ₹0.45L/Q2. Risky — users may switch to cheaper options. Better to grow volume than increase fare aggressively.
A9: Commission Rate (%) | B9: =$D$4*(1+(0.38*-0.2)) -> 1486536.7 | C9: =$D$4*(1+(0.38*-0.1)) -> 1547671.4 | D9: $D$4 | E9: =$D$4*(1+(0.38*0.1)) -> 1669940.6 | F9: =$D$4*(1+(0.38*0.2)) -> 1731075.3 | G9: MODERATE. Every 1% increase in commission = +₹0.5L/Q2. But drivers may resist if rate goes above 18%. Current 15% is competitive. Small increases (to 16%) are feasible.
A10: Number of Corporate Clients | B10: =$D$4*(1+(0.38*-0.2)) -> 1486536.7 | C10: =$D$4*(1+(0.38*-0.1)) -> 1547671.4 | D10: $D$4 | E10: =$D$4*(1+(0.38*0.1)) -> 1669940.6 | F10: =$D$4*(1+(0.38*0.2)) -> 1731075.3 | G10: HIGH IMPACT, LOW COST. Each new client = ₹26K+/month at ~90% margin. A BD hire (₹75K/month) paying for itself with just 3 new clients. Best ROI lever.
A11: Premium Subscribers | B11: =$D$4*(1+(0.12*-0.2)) -> 1570194.7 | C11: =$D$4*(1+(0.12*-0.1)) -> 1589500.3 | D11: $D$4 | E11: =$D$4*(1+(0.12*0.1)) -> 1628111.7 | F11: =$D$4*(1+(0.12*0.2)) -> 1647417.3 | G11: MODERATE. Each subscriber = ₹199/month, very low cost to serve. Growing from 520 to 600 in Apr adds ₹16K to Q2. Focus on in-app upsell conversion (currently 3.2% → target 5%).
A12: Advertising Revenue | B12: =$D$4*(1+(0.09*-0.2)) -> 1579847.5 | C12: =$D$4*(1+(0.09*-0.1)) -> 1594326.7 | D12: $D$4 | E12: =$D$4*(1+(0.09*0.1)) -> 1623285.3 | F12: =$D$4*(1+(0.09*0.2)) -> 1637764.5 | G12: LOW IMPACT. Ad revenue is small and grows automatically with users. No specific action needed — it follows the user growth trend.
A13: Marketing Spend | B13: =$D$4*(1+(-0.35*-0.2)) -> 1721422.4 | C13: =$D$4*(1+(-0.35*-0.1)) -> 1665114.2 | D13: $D$4 | E13: =$D$4*(1+(-0.35*0.1)) -> 1552497.8 | F13: =$D$4*(1+(-0.35*0.2)) -> 1496189.6 | G13: COST LEVER. Cutting marketing by 10% saves ₹40K/Q2 but may reduce user growth by ~15%, losing ₹1.1L revenue. Marketing ROI is positive — do not cut in the growth phase.
A15: KEY INSIGHT: Revenue is most sensitive to USER GROWTH and CORPORATE CLIENTS. Marketing spend (which drives users) has the highest ROI. Focus 70% of effort on user acquisition and corporate sales — everything else follows.
A17: ⚠ NOT a real startup. GatiGo is an academic design concept. All figures are hypothetical for learning purposes only. | D17: Model by Anjani Kumar Mishra

Sheet 💡 Insights
A1: GatiGo — Forecast Insights & Recommendations | What the numbers tell us
A2: This page explains what the revenue forecast means in simple business terms, and what GatiGo should do next based on the numbers.
A3: KEY INSIGHTS — What the forecast numbers are telling us
A4: 📊 | B4: Revenue is growing — but slowly in Q1
B5: Q1 revenue grew from ₹2.49L (Jan) to ₹3.82L (Mar) — a 53% increase in 3 months. That sounds good, but the company still lost ₹14.94L in Q1 because fixed costs (salaries, cloud, marketing = ₹4.63–5.17L/month) are much larger than the gross profit. This is normal for a new platform — you invest first, profit comes later.
A6: 🔑 | B6: Revenue depends heavily on user acquisition
B7: The sensitivity analysis shows that a 10% change in active users moves Q2 revenue by about 9.5%. No other single driver has that much impact. This means marketing spend (which grows users) is not a cost — it is an investment. Every ₹1 spent on digital ads that brings in a new user with 12-month LTV of ~₹2,400 is worth it, as long as CAC stays below ₹200.
A8: 🏢 | B8: Corporate partnerships are the best revenue source
B9: Corporate clients contribute ~37% of total revenue at ~90% gross margin (very low serving cost). Each new corporate client adds ₹26–35K/month of high-margin, recurring revenue. The forecast assumes corporate clients grow from 6 (Mar actual) to 18 (Dec forecast). This requires the BD hire made in March to convert the 3 pipeline deals currently in discussion.
A10: 📈 | B10: Intercity revenue could be a breakout stream
B11: Intercity launched mid-Feb and reached 80 rides in March. The forecast projects 440 rides by December. Each intercity ride earns ₹96 commission (₹800 fare × 12%) vs ₹25 for a city ride. If intercity volumes hit 500+ rides/month, it would add ₹48K revenue/month — worth prioritising.
A12: ⚠️ | B12: The model may be too optimistic — always have a backup plan
B13: The base case forecast assumes user growth of 8–9%/month. In Q1, actual growth was slower in some months due to launch challenges. Real-world growth is often lumpy. Always stress-test with the Low Growth scenario (Sheet 4) to ensure the company has enough cash. At the Low Growth scenario, full-year revenue is roughly ₹35L vs ₹55L in the Base Case.
A14: 💰 | B14: When will GatiGo break even?
B15: Break-even requires EBITDA = 0. In Q1, EBITDA was ₹(14.46L) — a big gap. The model projects break-even when: Total Rides ≥ 390/day AND fixed costs ≤ ₹5L/month. At the base-case growth rate, this is achievable in Q3 FY2026 (Jul–Sep) when rides should reach 350–450/day and corporate revenue doubles. Still requires careful cost management.
A17: RECOMMENDATIONS — What to do next, ranked by impact
A18: #1 | B18: Prioritise corporate client closure | Revenue | 30 days
B19: 3 corporate deals are in the pipeline. Assign the new BD hire as sole owner of these deals. Offer 30-day free trial to remove procurement friction. Each deal = ₹26K+/month at 90% margin. This alone could close ₹78K of the Q2 revenue gap.
A20: #2 | B20: Fix the cloud cost model | Cost | 14 days
B21: Cloud hosting was budgeted flat at ₹30K/month but actually scaled to ₹42K. For future forecasts, model it as ₹30K base + ₹0.50 per ride. This prevents recurring budget misses and gives a more accurate picture of unit economics.
A22: #3 | B22: Improve rides-per-user from 0.8 to 1.0 | Engagement | 60 days
B23: Existing users riding more often is pure margin — no extra acquisition cost. Implement: (a) weekly ride reminders via push notification, (b) loyalty milestone (₹50 credit after 10 rides/month), (c) commute scheduling feature. Each +0.1 rides/user adds ~₹85K annual revenue at current user base.
A24: #4 | B24: Launch intercity aggressively | Revenue | 45 days
B25: Intercity earns ₹96/ride vs ₹25/ride for city rides — 3.8x better economics. Add 3 new city pairs (Hyd–Bangalore, Hyd–Vijayawada, Hyd–Warangal). Target 250 intercity rides/month by end Q2. This adds ₹24K revenue/month.
A26: #5 | B26: Don't cut marketing in Q2 | Strategy | Ongoing
B27: Marketing ROI is strongly positive (LTV ₹2,400 vs CAC ₹111 in March). Cutting marketing to save ₹40K/month would cost more in lost revenue (₹1.1L+). Maintain or slightly increase digital spend; shift more to offline campus events where CAC is only ₹47 — 76% cheaper than digital.
B29: Model by Anjani Kumar Mishra
